{"trial_id": "096", "hyperparameters": {"space": [{"class_name": "Int", "config": {"name": "units", "default": null, "conditions": [], "min_value": 32, "max_value": 64, "step": 4, "sampling": "linear"}}, {"class_name": "Int", "config": {"name": "num_layers", "default": null, "conditions": [], "min_value": 1, "max_value": 6, "step": 1, "sampling": "linear"}}, {"class_name": "Boolean", "config": {"name": "dropout", "default": false, "conditions": []}}, {"class_name": "Choice", "config": {"name": "activation", "default": "relu", "conditions": [], "values": ["relu", "tanh"], "ordered": false}}, {"class_name": "Choice", "config": {"name": "optimizer", "default": "adam", "conditions": [], "values": ["adam", "SGD", "RMSprop", "Adadelta"], "ordered": false}}], "values": {"units": 36, "num_layers": 1, "dropout": false, "activation": "relu", "optimizer": "adam"}}, "metrics": {"metrics": {}}, "score": null, "best_step": 0, "status": "FAILED", "message": "Traceback (most recent call last):\n  File \"C:\\Users\\Jose\\anaconda3\\envs\\tf\\lib\\site-packages\\keras_tuner\\engine\\base_tuner.py\", line 266, in _try_run_and_update_trial\n    self._run_and_update_trial(trial, *fit_args, **fit_kwargs)\n  File \"C:\\Users\\Jose\\anaconda3\\envs\\tf\\lib\\site-packages\\keras_tuner\\engine\\base_tuner.py\", line 231, in _run_and_update_trial\n    results = self.run_trial(trial, *fit_args, **fit_kwargs)\n  File \"C:\\Users\\Jose\\anaconda3\\envs\\tf\\lib\\site-packages\\keras_tuner\\engine\\tuner.py\", line 287, in run_trial\n    obj_value = self._build_and_fit_model(trial, *args, **copied_kwargs)\n  File \"C:\\Users\\Jose\\anaconda3\\envs\\tf\\lib\\site-packages\\keras_tuner\\engine\\tuner.py\", line 214, in _build_and_fit_model\n    results = self.hypermodel.fit(hp, model, *args, **kwargs)\n  File \"C:\\Users\\Jose\\anaconda3\\envs\\tf\\lib\\site-packages\\keras_tuner\\engine\\hypermodel.py\", line 144, in fit\n    return model.fit(*args, **kwargs)\n  File \"C:\\Users\\Jose\\anaconda3\\envs\\tf\\lib\\site-packages\\keras\\utils\\traceback_utils.py\", line 70, in error_handler\n    raise e.with_traceback(filtered_tb) from None\n  File \"C:\\Users\\Jose\\anaconda3\\envs\\tf\\lib\\site-packages\\tensorflow\\python\\eager\\execute.py\", line 54, in quick_execute\n    tensors = pywrap_tfe.TFE_Py_Execute(ctx._handle, device_name, op_name,\ntensorflow.python.framework.errors_impl.FailedPreconditionError: {{function_node __wrapped__MergeV2Checkpoints_device_/job:localhost/replica:0/task:0/device:CPU:0}} Failed to rename: SINGLECLASS-ANN\\NSA/211CascadeSDM\\trial_096\\checkpoint_temp/part-00000-of-00001.data-00000-of-00001 to: SINGLECLASS-ANN\\NSA/211CascadeSDM\\trial_096\\checkpoint.data-00000-of-00001 : The process cannot access the file because it is being used by another process.\r\n; Broken pipe [Op:MergeV2Checkpoints]\n"}